<?xml version="1.0" ?>

<robot name = "lefthand" xmlns:xacro="http://ros.org/wiki/xacro">

    <!-- Include Materials -->
    <material name="Black">
        <color rgba="0.0 0.0 0.0 1.0"/>
    </material>

    <material name="Red">
        <color rgba="0.8 0.0 0.0 1.0"/>
    </material>

    <material name="White">
        <color rgba="1.0 1.0 1.0 1.0"/>
    </material>

    <!--constants-->
    <xacro:property name="deg_to_rad" value="0.01745329251994329577"/>
    <xacro:property name="M_SCALE" value="0.001 0.001 0.001"/>
    <xacro:property name="M_PI" value="3.14159"/>
    <xacro:property name="yaw" value="1.57"/>

    <!-- Carpals Box -->
    <xacro:property name="c_l" value="0.0437" />
    <xacro:property name="c_b" value="0.025" />
    <xacro:property name="c_h" value="0.02" />

    <!-- Metacarpals Box-->
    <xacro:property name="metc_l" value="0.06" />
    <xacro:property name="metc_b" value="0.025" />
    <xacro:property name="metc_h" value="0.0837" />

    <!-- Middle Finger -->
    <!-- Proximal -->
    <xacro:property name="proxlen" value="0.036"/>
    <xacro:property name="proxrad" value="0.010"/>
    <!-- Intermediate -->
    <xacro:property name="interlen" value="0.032"/>
    <xacro:property name="interrad" value="0.010"/>
    <!-- Distal -->
    <xacro:property name="distlen" value="0.040"/>
    <xacro:property name="distrad" value="0.010"/>

    <xacro:macro name="inertial_matrix" params="mass">
        <inertial>
            <mass value="${mass}"/>
            <inertia ixx="1.0" ixy="0.0" ixz="0.0" iyy="0.5" iyz="0.0" izz="1.0" />
        </inertial>
    </xacro:macro>

    <xacro:macro name="transmission_block" params="joint_name">
        <transmission name="tran1">
            <type>transmission_interface/SimpleTransmission</type>
            <joint name="${joint_name}">
    	      <hardwareInterface>hardware_interface/PositionJointInterface</hardwareInterface>
            </joint>
            <actuator name="motor1">
                <hardwareInterface>hardware_interface/PositionJointInterface</hardwareInterface>
                <mechanicalReduction>1</mechanicalReduction>
            </actuator>
        </transmission>
    </xacro:macro>

    <!-- /////////////////////////////////////////////////////////////////////////////// -->
    <!-- JOINTS AND LINKS -->

    <link name="base_link">
        <visual>
            <origin xyz="0 0 0" rpy="0 0 ${yaw}"/>
            <geometry>
                <box size="${c_l} ${c_b} ${c_h}"/>
            </geometry>
            <material name="Black"/>
        </visual>

        <!--xacro:inertial_matrix mass="1"/-->
    </link>

    <gazebo reference="base_link">
        <material>Gazebo/White</material>
    </gazebo>

    <joint name="carpal_metacarpal_roll" type="revolute">
        <origin xyz="0 0 0" rpy="0 0 0"/>
        <parent link="base_link"/>
        <child link="metacarpal_roll"/>
        <axis xyz="1 0 0"/>
        <limit effort="300" velocity="1" lower="1.57" upper="-1.57" />
        <dynamics damping="50" friction="1"/>
    </joint>
    <link name = "metacarpal_roll"/>
    <joint name="carpal_metacarpal_pitch" type="revolute">
        <origin xyz="0 0 0" rpy="0 0 0"/>
        <parent link="metacarpal_roll"/>
        <child link="metacarpal_pitch"/>
        <axis xyz="0 1 0"/>
        <limit effort="300" velocity="1" lower="-1.57" upper="1.57" />
        <dynamics damping="50" friction="1"/>
    </joint>
    <link name = "metacarpal_pitch"/>
    <joint name="carpal_metacarpal_yaw" type="revolute">
        <origin xyz="0 0 0" rpy="0 0 0"/>
        <parent link="metacarpal_pitch"/>
        <child link="metacarpal"/>
        <axis xyz="0 0 1"/>
        <limit effort="300" velocity="1" lower="-3.14" upper="0" />
        <dynamics damping="50" friction="1"/>
    </joint>
    <link name="metacarpal">
        <visual>
            <origin xyz="0 0 0.05185" rpy="0 0 ${yaw}"/>
            <geometry>
                <box size="${metc_l} ${metc_b} ${metc_h}"/>
            </geometry>
            <material name="White"/>
        </visual>
        <xacro:inertial_matrix mass="1"/>
    </link>

    <gazebo reference="metacarpal">
        <material>Gazebo/Black</material>
    </gazebo>
    <!-- ///////////////////////////////////////////////////////////////////////////////////////////////////////////////////// -->
    <!-- INDEX FINGER PROXIMAL-->
    <joint name="metacarpal_index" type="revolute">
        <origin xyz="0 0 0.0937" rpy="0 0 0"/>
        <parent link="metacarpal"/>
        <child link="index_p"/>
        <axis xyz="0 1 0"/>
        <limit effort="300" velocity="1" lower="0" upper="1.57" />
        <dynamics damping="50" friction="1"/>
    </joint>
    <link name="index_p">
        <visual>
            <origin xyz="0 0.018 0.018" rpy="0 0 ${yaw}"/>
            <geometry>
                <cylinder radius="${proxrad}" length="${proxlen}"/>
            </geometry>
            <material name="White"/>
        </visual>
        <xacro:inertial_matrix mass="1"/>
    </link>

    <!-- INDEX FINGER INTERMEDIATE-->
    <joint name="index_prox_inter" type="revolute">
        <origin xyz="0 0 ${proxlen}" rpy="0 0 0"/>
        <parent link="index_p"/>
        <child link="index_i"/>
        <axis xyz="0 1 0"/>
        <limit effort="300" velocity="1" lower="0" upper="1.57" />
        <dynamics damping="50" friction="1"/>
    </joint>
    <link name="index_i">
        <visual>
            <origin xyz="0 0.018 0.016" rpy="0 0 ${yaw}"/>
            <geometry>
                <cylinder radius="${interrad}" length="${interlen}"/>
            </geometry>
            <material name="White"/>
        </visual>


        <xacro:inertial_matrix mass="1"/>
    </link>
    <!-- INDEX FINGER DISTAL-->
    <joint name="index_inter_dist" type="revolute">
        <origin xyz="0 0 ${interlen}" rpy="0 0 0"/>
        <parent link="index_i"/>
        <child link="index_d"/>
        <axis xyz="0 1 0"/>
        <limit effort="300" velocity="1" lower="0" upper="1.57" />
        <dynamics damping="50" friction="1"/>
    </joint>
    <link name="index_d">
        <visual>
            <origin xyz="0 0.018 0.020" rpy="0 0 ${yaw}"/>
            <geometry>
                <cylinder radius="${distrad}" length="${distlen}"/>
            </geometry>
            <material name="White"/>
        </visual>

        <xacro:inertial_matrix mass="1"/>
    </link>


    <!-- ///////////////////////////////////////////////////////////////////////////////////////////////////////////////////// -->
    <!-- MIDDLE FINGER PROXIMAL-->
    <joint name="metacarpal_middle" type="revolute">
        <origin xyz="0 0 0.0937" rpy="0 0 0"/>
        <parent link="metacarpal"/>
        <child link="middle_p"/>
        <axis xyz="0 1 0"/>
        <limit effort="300" velocity="1" lower="0" upper="1.57" />
        <dynamics damping="50" friction="1"/>
    </joint>
    <link name="middle_p">
        <visual>
            <origin xyz="0 -0.018 0.018" rpy="0 0 ${yaw}"/>
            <geometry>
                <cylinder radius="${proxrad}" length="${proxlen}"/>
            </geometry>
            <material name="White"/>
        </visual>


        <xacro:inertial_matrix mass="1"/>
    </link>

    <!-- MIDDLE FINGER INTERMEDIATE-->
    <joint name="middle_prox_inter" type="revolute">
        <origin xyz="0 0 ${proxlen}" rpy="0 0 0"/>
        <parent link="middle_p"/>
        <child link="middle_i"/>
        <axis xyz="0 1 0"/>
        <limit effort="300" velocity="1" lower="0" upper="1.57" />
        <dynamics damping="50" friction="1"/>
    </joint>
    <link name="middle_i">
        <visual>
            <origin xyz="0 -0.018 0.016" rpy="0 0 ${yaw}"/>
            <geometry>
                <cylinder radius="${interrad}" length="${interlen}"/>
            </geometry>
            <material name="White"/>
        </visual>


        <xacro:inertial_matrix mass="1"/>
    </link>
    <!-- MIDDLE FINGER DISTAL-->
    <joint name="middle_inter_dist" type="revolute">
        <origin xyz="0 0 ${interlen}" rpy="0 0 0"/>
        <parent link="middle_i"/>
        <child link="middle_d"/>
        <axis xyz="0 1 0"/>
        <limit effort="300" velocity="1" lower="0" upper="1.57" />
        <dynamics damping="50" friction="1"/>
    </joint>
    <link name="middle_d">
        <visual>
            <origin xyz="0 -0.018 0.020" rpy="0 0 ${yaw}"/>
            <geometry>
                <cylinder radius="${distrad}" length="${distlen}"/>
            </geometry>
            <material name="White"/>
        </visual>


        <xacro:inertial_matrix mass="1"/>
    </link>
<!-- ///////////////////////////////////////////////////////////////////////////////////////////////////////////////////// -->
  <!-- Transmissions for ROS Control -->
    <xacro:transmission_block joint_name="carpal_metacarpal_roll"/>
    <xacro:transmission_block joint_name="carpal_metacarpal_pitch"/>
    <xacro:transmission_block joint_name="carpal_metacarpal_yaw"/>
    <xacro:transmission_block joint_name="metacarpal_index"/>
    <xacro:transmission_block joint_name="index_prox_inter"/>
    <xacro:transmission_block joint_name="index_inter_dist"/>
    <xacro:transmission_block joint_name="metacarpal_middle"/>
    <xacro:transmission_block joint_name="middle_prox_inter"/>
    <xacro:transmission_block joint_name="middle_inter_dist"/>

 <!-- ros_control plugin -->
  <gazebo>
    <plugin name="gazebo_ros_control" filename="libgazebo_ros_control.so">
      <robotNamespace>/lefthand</robotNamespace>
    </plugin>
  </gazebo>


</robot>